Workbook
Name ReportFrom: Settings!$B$5
Name ReportTo: Settings!$B$6

Sheet Cover
B2: BEYOND DESIGN
B3: Interior Design & Finishing
B4: ERP workbook — books, statements and import template
B5: Generated 2026-10-01 09:25 · all amounts in EGP · EMPTY TEMPLATE
B7: How to use | C7: Enter data only in the data sheets (blue text). Statements recalculate automatically. Import the whole file back into the app from Import & Export (same sheet and column names).
B8: Report period | C8: Change report_from / report_to on the Settings sheet (rows 5–6).
B9: Blue text | C9: Input cells — safe to edit.
B10: Black text | C10: Formulas — do not overwrite.
B11: Grey columns | C11: Helper formulas (collapsed with [+]); copy them down if you add rows beyond the prepared ones.
B12: Row 3 (grey italic) | C12: An example of the expected format in every data sheet — not imported.
B13: Accounts | C13: Leave account columns blank to use the defaults (by system role), or pick a code.
B14: Model Audit | C14: Must show OK on every line before you rely on the statements.
B16: Sheets
B17: Settings | C17: Company settings & report period
B18: Chart of Accounts | C18: Chart of accounts — edit codes and names freely; Role is the system tag (do not duplicate)
B19: Tax Codes | C19: VAT and withholding-tax codes with their e-invoice (ETA) tax type / sub-type. Rates are editable
B20: Business Units | C20: Business units (cost centres / projects). Overhead % = manual share of shared indirect costs
B21: Parties | C21: Customers & suppliers master — tax registration numbers and addresses are needed for e-invoices
B22: Partners | C22: Partners and their default profit share
B23: Partner Shares | C23: Ownership per business unit (overrides the default share)
B24: Fixed Assets | C24: Fixed asset register (its purchase, depreciation and disposal are journal entries with reference FA:<code>)
B25: Warehouses | C25: Warehouses / stores and their inventory account
B26: Stock Items | C26: Item master
B27: Price List | C27: Unit-rate price list (historical cost × (1 + markup) = client price)
B28: BOQ Lines | C28: Bills of quantities — one row per line; rows with the same BOQ Title + Business Unit form one BOQ
... B48: Model Audit | C48: integrity checks (must all be OK)
B50: Audit status | C50: ='Model Audit'!E11

Sheet Settings
A1: BEYOND DESIGN | SETTINGS
A2: Company settings & report period
A3: e.g. company_name | B3: BEYOND DESIGN
A4: Key | B4: Value
A5: report_from | B5: 46023
A6: report_to | B6: 46387
A7: appearance | B7: {}
A8: backup_keep | B8: 14
A9: bank_account
A10: bank_holder
A11: bank_iban
A12: bank_name
A13: bank_swift
A14: branding | B14: {}
A15: coa_v2 | B15: 1
A16: company_address
A17: company_city
A18: company_cr_no
A19: company_email
A20: company_legal_name
A21: company_name | B21: BEYOND DESIGN
A22: company_phone
A23: company_tagline | B23: Interior Design & Finishing
A24: company_tax_id
A25: company_website
A26: currency | B26: EGP
A27: entry_types
A28: eta_activity_code
A29: eta_branch_id | B29: 0
A30: eta_building
A31: eta_client_id
A32: eta_default_item_code
A33: eta_default_unit | B33: EA
A34: eta_doc_version | B34: 1.0
A35: eta_env | B35: preprod
A36: eta_governate
A37: eta_item_prefix | B37: EG
A38: eta_postal_code
A39: eta_region
A40: eta_signer_url
...

Sheet Chart of Accounts
A1: BEYOND DESIGN | CHART OF ACCOUNTS
A2: Chart of accounts — edit codes and names freely; Role is the system tag (do not duplicate)
A3: e.g. 6095 | B3: Cleaning & Hospitality | C3: Expense | D3: general_admin | H3: Yes
A4: Code | B4: Account Name | C4: Type | D4: Statement Line | E4: Normal Balance | F4: System Role | G4: Arabic Name | H4: Active
A5: 1010 | B5: Cash on Hand | C5: Asset | D5: cash | E5: =IF(OR(C5="Asset",C5="COGS",C5="Expense"),IF(OR(D5="accumulated_depreciation",D5="accumulated_amortization",D5="allowance_doubtful"),"Credit","Debit"),IF(OR(D5="drawings",D5="sales_discount"),"Debit","Credit")) | F5: cash | G5: النقدية بالصندوق | H5: Yes
A6: 1020 | B6: Bank Account | C6: Asset | D6: cash | E6: =IF(OR(C6="Asset",C6="COGS",C6="Expense"),IF(OR(D6="accumulated_depreciation",D6="accumulated_amortization",D6="allowance_doubtful"),"Credit","Debit"),IF(OR(D6="drawings",D6="sales_discount"),"Debit","Credit")) | F6: bank | G6: الحساب البنكي | H6: Yes
A7: 1030 | B7: Petty Cash | C7: Asset | D7: cash | E7: =IF(OR(C7="Asset",C7="COGS",C7="Expense"),IF(OR(D7="accumulated_depreciation",D7="accumulated_amortization",D7="allowance_doubtful"),"Credit","Debit"),IF(OR(D7="drawings",D7="sales_discount"),"Debit","Credit")) | G7: العهد النقدية | H7: Yes
A8: 1035 | B8: Cash Custody with Employees | C8: Asset | D8: other_current_asset | E8: =IF(OR(C8="Asset",C8="COGS",C8="Expense"),IF(OR(D8="accumulated_depreciation",D8="accumulated_amortization",D8="allowance_doubtful"),"Credit","Debit"),IF(OR(D8="drawings",D8="sales_discount"),"Debit","Credit")) | F8: custody | G8: عهد نقدية لدى العاملين | H8: Yes
A9: 1100 | B9: Accounts Receivable — Clients | C9: Asset | D9: receivable | E9: =IF(OR(C9="Asset",C9="COGS",C9="Expense"),IF(OR(D9="accumulated_depreciation",D9="accumulated_amortization",D9="allowance_doubtful"),"Credit","Debit"),IF(OR(D9="drawings",D9="sales_discount"),"Debit","Credit")) | F9: ar | G9: العملاء (المدينون) | H9: Yes
A10: 1120 | B10: Notes Receivable (Cheques Under Collection) | C10: Asset | D10: receivable | E10: =IF(OR(C10="Asset",C10="COGS",C10="Expense"),IF(OR(D10="accumulated_depreciation",D10="accumulated_amortization",D10="allowance_doubtful"),"Credit","Debit"),IF(OR(D10="drawings",D10="sales_discount"),"Debit","Credit")) | F10: notes_receivable | G10: أوراق القبض (شيكات تحت التحصيل) | H10: Yes
A11: 1150 | B11: Retention Receivable | C11: Asset | D11: receivable | E11: =IF(OR(C11="Asset",C11="COGS",C11="Expense"),IF(OR(D11="accumulated_depreciation",D11="accumulated_amortization",D11="allowance_doubtful"),"Credit","Debit"),IF(OR(D11="drawings",D11="sales_discount"),"Debit","Credit")) | G11: محتجزات لدى العملاء (ضمان أعمال) | H11: Yes
A12: 1160 | B12: Employee Advances | C12: Asset | D12: other_current_asset | E12: =IF(OR(C12="Asset",C12="COGS",C12="Expense"),IF(OR(D12="accumulated_depreciation",D12="accumulated_amortization",D12="allowance_doubtful"),"Credit","Debit"),IF(OR(D12="drawings",D12="sales_discount"),"Debit","Credit")) | G12: سلف العاملين | H12: Yes
A13: 1170 | B13: Due from Partners | C13: Asset | D13: other_current_asset | E13: =IF(OR(C13="Asset",C13="COGS",C13="Expense"),IF(OR(D13="accumulated_depreciation",D13="accumulated_amortization",D13="allowance_doubtful"),"Credit","Debit"),IF(OR(D13="drawings",D13="sales_discount"),"Debit","Credit")) | F13: partner_receivable | G13: مستحق من الشركاء | H13: Yes
A14: 1175 | B14: Loans Receivable (Short-term) | C14: Asset | D14: other_current_asset | E14: =IF(OR(C14="Asset",C14="COGS",C14="Expense"),IF(OR(D14="accumulated_depreciation",D14="accumulated_amortization",D14="allowance_doubtful"),"Credit","Debit"),IF(OR(D14="drawings",D14="sales_discount"),"Debit","Credit")) | F14: loans_receivable | G14: قروض ممنوحة للغير (قصيرة الأجل) | H14: Yes
A15: 1180 | B15: Unbilled Revenue (Work Done, Not Yet Invoiced) | C15: Asset | D15: other_current_asset | E15: =IF(OR(C15="Asset",C15="COGS",C15="Expense"),IF(OR(D15="accumulated_depreciation",D15="accumulated_amortization",D15="allowance_doubtful"),"Credit","Debit"),IF(OR(D15="drawings",D15="sales_discount"),"Debit","Credit")) | G15: إيرادات مستحقة غير مفوترة (أعمال منفذة) | H15: Yes
A16: 1185 | B16: Accrued Interest Receivable | C16: Asset | D16: other_current_asset | E16: =IF(OR(C16="Asset",C16="COGS",C16="Expense"),IF(OR(D16="accumulated_depreciation",D16="accumulated_amortization",D16="allowance_doubtful"),"Credit","Debit"),IF(OR(D16="drawings",D16="sales_discount"),"Debit","Credit")) | F16: interest_receivable | G16: فوائد مستحقة التحصيل | H16: Yes
A17: 1190 | B17: Allowance for Doubtful Accounts | C17: Asset | D17: allowance_doubtful | E17: =IF(OR(C17="Asset",C17="COGS",C17="Expense"),IF(OR(D17="accumulated_depreciation",D17="accumulated_amortization",D17="allowance_doubtful"),"Credit","Debit"),IF(OR(D17="drawings",D17="sales_discount"),"Debit","Credit")) | F17: doubtful_allowance | G17: مخصص الديون المشكوك في تحصيلها | H17: Yes
A18: 1200 | B18: Materials Inventory | C18: Asset | D18: inventory | E18: =IF(OR(C18="Asset",C18="COGS",C18="Expense"),IF(OR(D18="accumulated_depreciation",D18="accumulated_amortization",D18="allowance_doubtful"),"Credit","Debit"),IF(OR(D18="drawings",D18="sales_discount"),"Debit","Credit")) | F18: inventory | G18: مخزون الخامات | H18: Yes
A19: 1300 | B19: Prepaid Expenses | C19: Asset | D19: prepaid | E19: =IF(OR(C19="Asset",C19="COGS",C19="Expense"),IF(OR(D19="accumulated_depreciation",D19="accumulated_amortization",D19="allowance_doubtful"),"Credit","Debit"),IF(OR(D19="drawings",D19="sales_discount"),"Debit","Credit")) | G19: مصروفات مدفوعة مقدماً | H19: Yes
A20: 1310 | B20: Supplier Advances | C20: Asset | D20: prepaid | E20: =IF(OR(C20="Asset",C20="COGS",C20="Expense"),IF(OR(D20="accumulated_depreciation",D20="accumulated_amortization",D20="allowance_doubtful"),"Credit","Debit"),IF(OR(D20="drawings",D20="sales_discount"),"Debit","Credit")) | G20: دفعات مقدمة للموردين | H20: Yes
A21: 1320 | B21: VAT Recoverable (Input) | C21: Asset | D21: other_current_asset | E21: =IF(OR(C21="Asset",C21="COGS",C21="Expense"),IF(OR(D21="accumulated_depreciation",D21="accumulated_amortization",D21="allowance_doubtful"),"Credit","Debit"),IF(OR(D21="drawings",D21="sales_discount"),"Debit","Credit")) | F21: vat_input | G21: ضريبة القيمة المضافة (مدخلات) | H21: Yes
A22: 1330 | B22: Withholding Tax Receivable (deducted by clients) | C22: Asset | D22: other_current_asset | E22: =IF(OR(C22="Asset",C22="COGS",C22="Expense"),IF(OR(D22="accumulated_depreciation",D22="accumulated_amortization",D22="allowance_doubtful"),"Credit","Debit"),IF(OR(D22="drawings",D22="sales_discount"),"Debit","Credit")) | F22: wht_receivable | G22: ضريبة خصم وتحصيل لدى العملاء | H22: Yes
A23: 1340 | B23: Letters of Guarantee — Cash Margin | C23: Asset | D23: other_current_asset | E23: =IF(OR(C23="Asset",C23="COGS",C23="Expense"),IF(OR(D23="accumulated_depreciation",D23="accumulated_amortization",D23="allowance_doubtful"),"Credit","Debit"),IF(OR(D23="drawings",D23="sales_discount"),"Debit","Credit")) | G23: غطاء خطابات الضمان | H23: Yes
A24: 1400 | B24: Furniture & Office Equipment | C24: Asset | D24: fixed_asset | E24: =IF(OR(C24="Asset",C24="COGS",C24="Expense"),IF(OR(D24="accumulated_depreciation",D24="accumulated_amortization",D24="allowance_doubtful"),"Credit","Debit"),IF(OR(D24="drawings",D24="sales_discount"),"Debit","Credit")) | F24: fixed_asset | G24: أثاث ومعدات مكتبية | H24: Yes
A25: 1410 | B25: Tools & Site Equipment | C25: Asset | D25: fixed_asset | E25: =IF(OR(C25="Asset",C25="COGS",C25="Expense"),IF(OR(D25="accumulated_depreciation",D25="accumulated_amortization",D25="allowance_doubtful"),"Credit","Debit"),IF(OR(D25="drawings",D25="sales_discount"),"Debit","Credit")) | G25: عدد ومعدات مواقع | H25: Yes
A26: 1415 | B26: Rental Equipment (Scaffolding, Elevators, Cradles) | C26: Asset | D26: fixed_asset | E26: =IF(OR(C26="Asset",C26="COGS",C26="Expense"),IF(OR(D26="accumulated_depreciation",D26="accumulated_amortization",D26="allowance_doubtful"),"Credit","Debit"),IF(OR(D26="drawings",D26="sales_discount"),"Debit","Credit")) | F26: rental_fleet | G26: معدات التأجير (سقالات، مصاعد، سقالات معلقة) | H26: Yes
A27: 1416 | B27: Accumulated Depreciation — Rental Equipment | C27: Asset | D27: accumulated_depreciation | E27: =IF(OR(C27="Asset",C27="COGS",C27="Expense"),IF(OR(D27="accumulated_depreciation",D27="accumulated_amortization",D27="allowance_doubtful"),"Credit","Debit"),IF(OR(D27="drawings",D27="sales_discount"),"Debit","Credit")) | F27: rental_accum | G27: مجمع إهلاك معدات التأجير | H27: Yes
A28: 1420 | B28: Vehicles | C28: Asset | D28: fixed_asset | E28: =IF(OR(C28="Asset",C28="COGS",C28="Expense"),IF(OR(D28="accumulated_depreciation",D28="accumulated_amortization",D28="allowance_doubtful"),"Credit","Debit"),IF(OR(D28="drawings",D28="sales_discount"),"Debit","Credit")) | G28: سيارات | H28: Yes
A29: 1430 | B29: Computers & IT Equipment | C29: Asset | D29: fixed_asset | E29: =IF(OR(C29="Asset",C29="COGS",C29="Expense"),IF(OR(D29="accumulated_depreciation",D29="accumulated_amortization",D29="allowance_doubtful"),"Credit","Debit"),IF(OR(D29="drawings",D29="sales_discount"),"Debit","Credit")) | G29: أجهزة حاسب ومعدات تقنية | H29: Yes
A30: 1440 | B30: Land | C30: Asset | D30: fixed_asset | E30: =IF(OR(C30="Asset",C30="COGS",C30="Expense"),IF(OR(D30="accumulated_depreciation",D30="accumulated_amortization",D30="allowance_doubtful"),"Credit","Debit"),IF(OR(D30="drawings",D30="sales_discount"),"Debit","Credit")) | G30: أراضي | H30: Yes
A31: 1450 | B31: Buildings & Leasehold Improvements | C31: Asset | D31: fixed_asset | E31: =IF(OR(C31="Asset",C31="COGS",C31="Expense"),IF(OR(D31="accumulated_depreciation",D31="accumulated_amortization",D31="allowance_doubtful"),"Credit","Debit"),IF(OR(D31="drawings",D31="sales_discount"),"Debit","Credit")) | G31: مباني وتحسينات أماكن مستأجرة | H31: Yes
A32: 1460 | B32: Assets Under Construction | C32: Asset | D32: fixed_asset | E32: =IF(OR(C32="Asset",C32="COGS",C32="Expense"),IF(OR(D32="accumulated_depreciation",D32="accumulated_amortization",D32="allowance_doubtful"),"Credit","Debit"),IF(OR(D32="drawings",D32="sales_discount"),"Debit","Credit")) | G32: مشروعات تحت التنفيذ | H32: Yes
A33: 1490 | B33: Accumulated Depreciation | C33: Asset | D33: accumulated_depreciation | E33: =IF(OR(C33="Asset",C33="COGS",C33="Expense"),IF(OR(D33="accumulated_depreciation",D33="accumulated_amortization",D33="allowance_doubtful"),"Credit","Debit"),IF(OR(D33="drawings",D33="sales_discount"),"Debit","Credit")) | F33: accum_depreciation | G33: مجمع الإهلاك | H33: Yes
A34: 1500 | B34: Software & Licences | C34: Asset | D34: intangible | E34: =IF(OR(C34="Asset",C34="COGS",C34="Expense"),IF(OR(D34="accumulated_depreciation",D34="accumulated_amortization",D34="allowance_doubtful"),"Credit","Debit"),IF(OR(D34="drawings",D34="sales_discount"),"Debit","Credit")) | F34: intangible | G34: برامج وتراخيص | H34: Yes
A35: 1510 | B35: Brand, Website & Design Library | C35: Asset | D35: intangible | E35: =IF(OR(C35="Asset",C35="COGS",C35="Expense"),IF(OR(D35="accumulated_depreciation",D35="accumulated_amortization",D35="allowance_doubtful"),"Credit","Debit"),IF(OR(D35="drawings",D35="sales_discount"),"Debit","Credit")) | G35: العلامة التجارية والموقع ومكتبة التصميمات | H35: Yes
A36: 1520 | B36: Goodwill | C36: Asset | D36: intangible | E36: =IF(OR(C36="Asset",C36="COGS",C36="Expense"),IF(OR(D36="accumulated_depreciation",D36="accumulated_amortization",D36="allowance_doubtful"),"Credit","Debit"),IF(OR(D36="drawings",D36="sales_discount"),"Debit","Credit")) | G36: الشهرة | H36: Yes
A37: 1590 | B37: Accumulated Amortization | C37: Asset | D37: accumulated_amortization | E37: =IF(OR(C37="Asset",C37="COGS",C37="Expense"),IF(OR(D37="accumulated_depreciation",D37="accumulated_amortization",D37="allowance_doubtful"),"Credit","Debit"),IF(OR(D37="drawings",D37="sales_discount"),"Debit","Credit")) | F37: accum_amortization | G37: مجمع الاستهلاك | H37: Yes
A38: 1600 | B38: Security Deposits | C38: Asset | D38: other_noncurrent_asset | E38: =IF(OR(C38="Asset",C38="COGS",C38="Expense"),IF(OR(D38="accumulated_depreciation",D38="accumulated_amortization",D38="allowance_doubtful"),"Credit","Debit"),IF(OR(D38="drawings",D38="sales_discount"),"Debit","Credit")) | G38: تأمينات لدى الغير | H38: Yes
A39: 1610 | B39: Loans Receivable (Long-term) | C39: Asset | D39: other_noncurrent_asset | E39: =IF(OR(C39="Asset",C39="COGS",C39="Expense"),IF(OR(D39="accumulated_depreciation",D39="accumulated_amortization",D39="allowance_doubtful"),"Credit","Debit"),IF(OR(D39="drawings",D39="sales_discount"),"Debit","Credit")) | F39: loans_receivable_lt | G39: قروض ممنوحة للغير (طويلة الأجل) | H39: Yes
A40: 1700 | B40: Long-term Investments | C40: Asset | D40: investment | E40: =IF(OR(C40="Asset",C40="COGS",C40="Expense"),IF(OR(D40="accumulated_depreciation",D40="accumulated_amortization",D40="allowance_doubtful"),"Credit","Debit"),IF(OR(D40="drawings",D40="sales_discount"),"Debit","Credit")) | F40: investments | G40: استثمارات طويلة الأجل | H40: Yes
...

Sheet Tax Codes
A1: BEYOND DESIGN | TAX CODES
A2: VAT and withholding-tax codes with their e-invoice (ETA) tax type / sub-type. Rates are editable
A3: e.g. VAT14 | B3: VAT 14% (standard) | C3: ضريبة القيمة المضافة 14% | D3: vat | E3: 14% | F3: T1 | G3: V009 | H3: Yes
A4: Code | B4: Name | C4: Arabic Name | D4: Kind | E4: Rate | F4: ETA Tax Type | G4: ETA Sub-type | H4: Active
A5: VAT-EXEMPT | B5: VAT exempt | C5: معفى من ضريبة القيمة المضافة | D5: vat | E5: 0 | F5: T1 | G5: V003 | H5: Yes
A6: VAT0-EXP | B6: VAT 0% — exports | C6: ضريبة القيمة المضافة 0% — صادرات | D6: vat | E6: 0 | F6: T1 | G6: V001 | H6: Yes
A7: VAT14 | B7: VAT 14% (standard) | C7: ضريبة القيمة المضافة 14% | D7: vat | E7: 0.14 | F7: T1 | G7: V009 | H7: Yes
A8: WHT1-C | B8: WHT 1% — contracting | C8: خصم وتحصيل 1% — مقاولات | D8: wht | E8: 0.01 | F8: T4 | G8: W001 | H8: Yes
A9: WHT1-S | B9: WHT 1% — supplies | C9: خصم وتحصيل 1% — توريدات | D9: wht | E9: 0.01 | F9: T4 | G9: W002 | H9: Yes
A10: WHT3 | B10: WHT 3% — services | C10: خصم وتحصيل 3% — خدمات | D10: wht | E10: 0.03 | F10: T4 | G10: W004 | H10: Yes
A11: WHT5 | B11: WHT 5% — professional fees | C11: خصم وتحصيل 5% — أتعاب مهنية | D11: wht | E11: 0.05 | F11: T4 | G11: W010 | H11: Yes

Sheet Business Units
A1: BEYOND DESIGN | BUSINESS UNITS
A2: Business units (cost centres / projects). Overhead % = manual share of shared indirect costs
A3: e.g. PRJ-2026-004 | B3: Villa 12 — Mr. Aly | C3: Villa | D3: New Cairo | E3: 420 | F3: 2026-10-01 | G3: In Progress | H3: Cost-Plus % | I3: 25% | K3: 30%
A4: Code | B4: Name / Client | C4: Type | D4: Location | E4: Area (m²) | F4: Start Date | G4: Status | H4: Billing Basis | I4: Fee % | J4: Contract Value | K4: Overhead Allocation % | L4: Customer | M4: Notes

Sheet Parties
A1: BEYOND DESIGN | PARTIES
A2: Customers & suppliers master — tax registration numbers and addresses are needed for e-invoices
A3: e.g. Palm Hills Developments | B3: customer | C3: B | D3: 123456789 | F3: EG | G3: Giza | H3: 6th of October | I3: 26th of July Axis | J3: 12 | N3: VAT14 | O3: WHT1-C
A4: Name | B4: Type | C4: Receiver Type | D4: Tax Registration No. | E4: National ID | F4: Country | G4: Governorate | H4: City / Region | I4: Street | J4: Building No. | K4: Postal Code | L4: Email | M4: Phone | N4: Default VAT | O4: Default WHT | P4: Notes | Q4: Category | R4: Contact Person | S4: Other Phone | T4: WhatsApp | U4: Trade / Specialty | V4: Vehicle / Plate | W4: Bank Details

Sheet Partners
A1: BEYOND DESIGN | PARTNERS
A2: Partners and their default profit share
A3: e.g. Partner name | B3: 25% | C3: Yes
A4: Partner | B4: Default Share % | C4: Still a Partner | D4: Joined | E4: Left | F4: Interest on Capital % | G4: Loan Interest % | H4: Notes

Sheet Partner Shares
A1: BEYOND DESIGN | PARTNER SHARES
A2: Ownership per business unit (overrides the default share)
A3: e.g. Partner name | B3: PRJ-2026-004 | C3: 25%
A4: Partner | B4: Business Unit | C4: Share %

Sheet Fixed Assets
A1: BEYOND DESIGN | FIXED ASSETS
A2: Fixed asset register (its purchase, depreciation and disposal are journal entries with reference FA:<code>)
A3: e.g. FA-0001 | B3: Site pickup truck | C3: 1420 | F3: 2026-01-15 | G3: 600000 | I3: 60
A4: Asset Code | B4: Asset | C4: Asset Account | D4: Accumulated Depreciation Account | E4: Depreciation Expense Account | F4: Date Acquired | G4: Cost | H4: Residual Value | I4: Useful Life (months) | J4: Depreciate From (YYYY-MM) | K4: Depreciation Before Registering | L4: Business Unit | M4: Location | N4: Serial / Plate No. | O4: Notes | P4: Depreciation Method | Q4: Declining Factor | R4: Monthly Depreciation (straight line) | S4: Depreciation to Report End | T4: Book Value at Report End
R5: =IF(OR(A5="",N(I5)=0),0,ROUND((N(G5)-N(H5))/N(I5),2)) | S5: =IF(A5="","",IFERROR(MIN(N(G5)-N(H5),MAX(N(K5),R5*MAX(0,(YEAR(ReportTo)-YEAR(IF(J5<>"",DATE(LEFT(J5,4),MID(J5,6,2),1),F5)))*12+MONTH(ReportTo)-MONTH(IF(J5<>"",DATE(LEFT(J5,4),MID(J5,6,2),1),F5))+1))),"")) | T5: =IF(A5="","",IFERROR(N(G5)-N(S5),""))
R6: =IF(OR(A6="",N(I6)=0),0,ROUND((N(G6)-N(H6))/N(I6),2)) | S6: =IF(A6="","",IFERROR(MIN(N(G6)-N(H6),MAX(N(K6),R6*MAX(0,(YEAR(ReportTo)-YEAR(IF(J6<>"",DATE(LEFT(J6,4),MID(J6,6,2),1),F6)))*12+MONTH(ReportTo)-MONTH(IF(J6<>"",DATE(LEFT(J6,4),MID(J6,6,2),1),F6))+1))),"")) | T6: =IF(A6="","",IFERROR(N(G6)-N(S6),""))
R7: =IF(OR(A7="",N(I7)=0),0,ROUND((N(G7)-N(H7))/N(I7),2)) | S7: =IF(A7="","",IFERROR(MIN(N(G7)-N(H7),MAX(N(K7),R7*MAX(0,(YEAR(ReportTo)-YEAR(IF(J7<>"",DATE(LEFT(J7,4),MID(J7,6,2),1),F7)))*12+MONTH(ReportTo)-MONTH(IF(J7<>"",DATE(LEFT(J7,4),MID(J7,6,2),1),F7))+1))),"")) | T7: =IF(A7="","",IFERROR(N(G7)-N(S7),""))
R8: =IF(OR(A8="",N(I8)=0),0,ROUND((N(G8)-N(H8))/N(I8),2)) | S8: =IF(A8="","",IFERROR(MIN(N(G8)-N(H8),MAX(N(K8),R8*MAX(0,(YEAR(ReportTo)-YEAR(IF(J8<>"",DATE(LEFT(J8,4),MID(J8,6,2),1),F8)))*12+MONTH(ReportTo)-MONTH(IF(J8<>"",DATE(LEFT(J8,4),MID(J8,6,2),1),F8))+1))),"")) | T8: =IF(A8="","",IFERROR(N(G8)-N(S8),""))
R9: =IF(OR(A9="",N(I9)=0),0,ROUND((N(G9)-N(H9))/N(I9),2)) | S9: =IF(A9="","",IFERROR(MIN(N(G9)-N(H9),MAX(N(K9),R9*MAX(0,(YEAR(ReportTo)-YEAR(IF(J9<>"",DATE(LEFT(J9,4),MID(J9,6,2),1),F9)))*12+MONTH(ReportTo)-MONTH(IF(J9<>"",DATE(LEFT(J9,4),MID(J9,6,2),1),F9))+1))),"")) | T9: =IF(A9="","",IFERROR(N(G9)-N(S9),""))
R10: =IF(OR(A10="",N(I10)=0),0,ROUND((N(G10)-N(H10))/N(I10),2)) | S10: =IF(A10="","",IFERROR(MIN(N(G10)-N(H10),MAX(N(K10),R10*MAX(0,(YEAR(ReportTo)-YEAR(IF(J10<>"",DATE(LEFT(J10,4),MID(J10,6,2),1),F10)))*12+MONTH(ReportTo)-MONTH(IF(J10<>"",DATE(LEFT(J10,4),MID(J10,6,2),1),F10))+1))),"")) | T10: =IF(A10="","",IFERROR(N(G10)-N(S10),""))
R11: =IF(OR(A11="",N(I11)=0),0,ROUND((N(G11)-N(H11))/N(I11),2)) | S11: =IF(A11="","",IFERROR(MIN(N(G11)-N(H11),MAX(N(K11),R11*MAX(0,(YEAR(ReportTo)-YEAR(IF(J11<>"",DATE(LEFT(J11,4),MID(J11,6,2),1),F11)))*12+MONTH(ReportTo)-MONTH(IF(J11<>"",DATE(LEFT(J11,4),MID(J11,6,2),1),F11))+1))),"")) | T11: =IF(A11="","",IFERROR(N(G11)-N(S11),""))
R12: =IF(OR(A12="",N(I12)=0),0,ROUND((N(G12)-N(H12))/N(I12),2)) | S12: =IF(A12="","",IFERROR(MIN(N(G12)-N(H12),MAX(N(K12),R12*MAX(0,(YEAR(ReportTo)-YEAR(IF(J12<>"",DATE(LEFT(J12,4),MID(J12,6,2),1),F12)))*12+MONTH(ReportTo)-MONTH(IF(J12<>"",DATE(LEFT(J12,4),MID(J12,6,2),1),F12))+1))),"")) | T12: =IF(A12="","",IFERROR(N(G12)-N(S12),""))
R13: =IF(OR(A13="",N(I13)=0),0,ROUND((N(G13)-N(H13))/N(I13),2)) | S13: =IF(A13="","",IFERROR(MIN(N(G13)-N(H13),MAX(N(K13),R13*MAX(0,(YEAR(ReportTo)-YEAR(IF(J13<>"",DATE(LEFT(J13,4),MID(J13,6,2),1),F13)))*12+MONTH(ReportTo)-MONTH(IF(J13<>"",DATE(LEFT(J13,4),MID(J13,6,2),1),F13))+1))),"")) | T13: =IF(A13="","",IFERROR(N(G13)-N(S13),""))
R14: =IF(OR(A14="",N(I14)=0),0,ROUND((N(G14)-N(H14))/N(I14),2)) | S14: =IF(A14="","",IFERROR(MIN(N(G14)-N(H14),MAX(N(K14),R14*MAX(0,(YEAR(ReportTo)-YEAR(IF(J14<>"",DATE(LEFT(J14,4),MID(J14,6,2),1),F14)))*12+MONTH(ReportTo)-MONTH(IF(J14<>"",DATE(LEFT(J14,4),MID(J14,6,2),1),F14))+1))),"")) | T14: =IF(A14="","",IFERROR(N(G14)-N(S14),""))
R15: =IF(OR(A15="",N(I15)=0),0,ROUND((N(G15)-N(H15))/N(I15),2)) | S15: =IF(A15="","",IFERROR(MIN(N(G15)-N(H15),MAX(N(K15),R15*MAX(0,(YEAR(ReportTo)-YEAR(IF(J15<>"",DATE(LEFT(J15,4),MID(J15,6,2),1),F15)))*12+MONTH(ReportTo)-MONTH(IF(J15<>"",DATE(LEFT(J15,4),MID(J15,6,2),1),F15))+1))),"")) | T15: =IF(A15="","",IFERROR(N(G15)-N(S15),""))
R16: =IF(OR(A16="",N(I16)=0),0,ROUND((N(G16)-N(H16))/N(I16),2)) | S16: =IF(A16="","",IFERROR(MIN(N(G16)-N(H16),MAX(N(K16),R16*MAX(0,(YEAR(ReportTo)-YEAR(IF(J16<>"",DATE(LEFT(J16,4),MID(J16,6,2),1),F16)))*12+MONTH(ReportTo)-MONTH(IF(J16<>"",DATE(LEFT(J16,4),MID(J16,6,2),1),F16))+1))),"")) | T16: =IF(A16="","",IFERROR(N(G16)-N(S16),""))
... R204: =IF(OR(A204="",N(I204)=0),0,ROUND((N(G204)-N(H204))/N(I204),2)) | S204: =IF(A204="","",IFERROR(MIN(N(G204)-N(H204),MAX(N(K204),R204*MAX(0,(YEAR(ReportTo)-YEAR(IF(J204<>"",DATE(LEFT(J204,4),MID(J204,6,2),1),F204)))*12+MONTH(ReportTo)-MONTH(IF(J204<>"",DATE(LEFT(J204,4),MID(J204,6,2),1),F204))+1))),"")) | T204: =IF(A204="","",IFERROR(N(G204)-N(S204),""))

Sheet Warehouses
A1: BEYOND DESIGN | WAREHOUSES
A2: Warehouses / stores and their inventory account
A3: e.g. Site Store — Villa 12 | B3: New Cairo | C3: 1200
A4: Warehouse | B4: Location | C4: Inventory Account
A5: Main Store | C5: 1200

Sheet Stock Items
A1: BEYOND DESIGN | STOCK ITEMS
A2: Item master
A3: e.g. Ceramic tiles 60×60 | B3: m2 | C3: CT-6060 | D3: 50
A4: Item | B4: Unit | C4: SKU | D4: Reorder Level

Sheet Price List
A1: BEYOND DESIGN | PRICE LIST
A2: Unit-rate price list (historical cost × (1 + markup) = client price)
A3: e.g. أعمال البياض | B3: 3.1 | D3: بياض حوائط | E3: م٢ | F3: 219.23 | G3: 30%
A4: Category | B4: Item No. | C4: Sub-category | D4: Description | E4: Unit | F4: Unit Cost | G4: Markup % | H4: Client Price | I4: Notes | J4: ETA Item Code

Sheet BOQ Lines
A1: BEYOND DESIGN | BOQ LINES
A2: Bills of quantities — one row per line; rows with the same BOQ Title + Business Unit form one BOQ
A3: e.g. Interior works | B3: PRJ-2026-004 | C3: Rev 01 | D3: 2026-10-01 | G3: أعمال البياض | I3: 3.1 | J3: بياض حوائط | K3: م٢ | L3: 320 | M3: 285 | N3: 219.23
A4: BOQ Title | B4: Business Unit | C4: Revision | D4: Date | E4: Client | F4: Location | G4: Category | H4: Sub-category | I4: Item No. | J4: Description | K4: Unit | L4: Qty | M4: Unit Price | N4: Unit Cost | O4: Amount
O5: =ROUND(N(L5)*N(M5),2)
O6: =ROUND(N(L6)*N(M6),2)
O7: =ROUND(N(L7)*N(M7),2)
O8: =ROUND(N(L8)*N(M8),2)
O9: =ROUND(N(L9)*N(M9),2)
O10: =ROUND(N(L10)*N(M10),2)
O11: =ROUND(N(L11)*N(M11),2)
O12: =ROUND(N(L12)*N(M12),2)
O13: =ROUND(N(L13)*N(M13),2)
O14: =ROUND(N(L14)*N(M14),2)
O15: =ROUND(N(L15)*N(M15),2)
O16: =ROUND(N(L16)*N(M16),2)
... O204: =ROUND(N(L204)*N(M204),2)

Sheet Direct Costs
A1: BEYOND DESIGN | DIRECT COSTS
A2: Direct costs (cost of revenue) per business unit — materials, subcontractors, site work
A3: e.g. 2026-10-03 | B3: PRJ-2026-004 | C3: 5010 | D3: Cement 50 kg | E3: El-Masry Supplies | H3: 16 | I3: bag | J3: 240 | L3: 2000 | M3: Cash | P3: VAT14 | Q3: WHT1-S
A4: Date | B4: Business Unit | C4: Cost Account | D4: Description | E4: Supplier | F4: Deal Ref. | G4: Deal Status | H4: Qty | I4: Unit | J4: Unit Cost | K4: Negotiation Discount | L4: Paid Now | M4: Payment Method | N4: Paid From | O4: Payable Account | P4: VAT Code | Q4: WHT Code | R4: Total Cost | S4: Input VAT | T4: WHT Withheld | U4: Unpaid | V4: account (effective) | W4: paid_from (effective) | X4: payable_account (effective) | Y4: vat_input account | Z4: wht_payable account | AA4: leg 1 type | AB4: leg 2 type | AC4: leg 3 type | AD4: leg 4 type | AE4: leg 5 type | AF4: revenue | AG4: cost of sales | AH4: expenses | AI4: operating expenses | AJ4: payables | AK4: accruals | AL4: unknown account
R5: =ROUND(N(H5)*N(J5)-N(K5),2) | S5: =ROUND(R5*IFERROR(VLOOKUP(P5,'Tax Codes'!$A$5:$E$300,5,FALSE),0),2) | T5: =ROUND(R5*IFERROR(VLOOKUP(Q5,'Tax Codes'!$A$5:$E$300,5,FALSE),0),2) | U5: =R5+S5-T5-N(L5) | V5: =IF(C5="",INDEX('Chart of Accounts'!$A$5:$A$3000,MATCH("materials",'Chart of Accounts'!$F$5:$F$3000,0)),C5&"") | W5: =IF(N5="",INDEX('Chart of Accounts'!$A$5:$A$3000,MATCH("bank",'Chart of Accounts'!$F$5:$F$3000,0)),N5&"") | X5: =IF(O5="",INDEX('Chart of Accounts'!$A$5:$A$3000,MATCH("ap",'Chart of Accounts'!$F$5:$F$3000,0)),O5&"") | Y5: =INDEX('Chart of Accounts'!$A$5:$A$3000,MATCH("vat_input",'Chart of Accounts'!$F$5:$F$3000,0)) | Z5: =INDEX('Chart of Accounts'!$A$5:$A$3000,MATCH("wht_payable",'Chart of Accounts'!$F$5:$F$3000,0)) | AA5: =IFERROR(INDEX('Chart of Accounts'!$C$5:$C$3000,MATCH(V5&"",'Chart of Accounts'!$A$5:$A$3000,0))&"|"&INDEX('Chart of Accounts'!$D$5:$D$3000,MATCH(V5&"",'Chart of Accounts'!$A$5:$A$3000,0)),"") | AB5: =IFERROR(INDEX('Chart of Accounts'!$C$5:$C$3000,MATCH(Y5&"",'Chart of Accounts'!$A$5:$A$3000,0))&"|"&INDEX('Chart of Accounts'!$D$5:$D$3000,MATCH(Y5&"",'Chart of Accounts'!$A$5:$A$3000,0)),"") | AC5: =IFERROR(INDEX('Chart of Accounts'!$C$5:$C$3000,MATCH(W5&"",'Chart of Accounts'!$A$5:$A$3000,0))&"|"&INDEX('Chart of Accounts'!$D$5:$D$3000,MATCH(W5&"",'Chart of Accounts'!$A$5:$A$3000,0)),"") | AD5: =IFERROR(INDEX('Chart of Accounts'!$C$5:$C$3000,MATCH(X5&"",'Chart of Accounts'!$A$5:$A$3000,0))&"|"&INDEX('Chart of Accounts'!$D$5:$D$3000,MATCH(X5&"",'Chart of Accounts'!$A$5:$A$3000,0)),"") | AE5: =IFERROR(INDEX('Chart of Accounts'!$C$5:$C$3000,MATCH(Z5&"",'Chart of Accounts'!$A$5:$A$3000,0))&"|"&INDEX('Chart of Accounts'!$D$5:$D$3000,MATCH(Z5&"",'Chart of Accounts'!$A$5:$A$3000,0)),"") | AF5: =IF(LEFT(AA5,8)="Revenue|",-N(R5),0)+IF(LEFT(AB5,8)="Revenue|",-N(S5),0)+IF(LEFT(AC5,8)="Revenue|",N(L5),0)+IF(LEFT(AD5,8)="Revenue|",N(U5),0)+IF(LEFT(AE5,8)="Revenue|",N(T5),0) | AG5: =IF(LEFT(AA5,5)="COGS|",N(R5),0)+IF(LEFT(AB5,5)="COGS|",N(S5),0)+IF(LEFT(AC5,5)="COGS|",-N(L5),0)+IF(LEFT(AD5,5)="COGS|",-N(U5),0)+IF(LEFT(AE5,5)="COGS|",-N(T5),0) | AH5: =IF(LEFT(AA5,8)="Expense|",N(R5),0)+IF(LEFT(AB5,8)="Expense|",N(S5),0)+IF(LEFT(AC5,8)="Expense|",-N(L5),0)+IF(LEFT(AD5,8)="Expense|",-N(U5),0)+IF(LEFT(AE5,8)="Expense|",-N(T5),0) | AI5: =IF(ISNUMBER(MATCH(AA5,{"Expense|employee","Expense|general_admin","Expense|marketing","Expense|utilities","Expense|other_operating"},0)),N(R5),0)+IF(ISNUMBER(MATCH(AB5,{"Expense|employee","Expense|general_admin","Expense|marketing","Expense|utilities","Expense|other_operating"},0)),N(S5),0)+IF(ISNUMBER(MATCH(AC5,{"Expense|employee","Expense|general_admin","Expense|marketing","Expense|utilities","Expense|other_operating"},0)),-N(L5),0)+IF(ISNUMBER(MATCH(AD5,{"Expense|employee","Expense|general_admin","Expense|marketing","Expense|utilities","Expense|other_operating"},0)),-N(U5),0)+IF(ISNUMBER(MATCH(AE5,{"Expense|employee","Expense|general_admin","Expense|marketing","Expense|utilities","Expense|other_operating"},0)),-N(T5),0) | AJ5: =IF(AA5="Liability|payable",-N(R5),0)+IF(AB5="Liability|payable",-N(S5),0)+IF(AC5="Liability|payable",N(L5),0)+IF(AD5="Liability|payable",N(U5),0)+IF(AE5="Liability|payable",N(T5),0) | AK5: =IF(AA5="Liability|accrued",-N(R5),0)+IF(AB5="Liability|accrued",-N(S5),0)+IF(AC5="Liability|accrued",N(L5),0)+IF(AD5="Liability|accrued",N(U5),0)+IF(AE5="Liability|accrued",N(T5),0) | AL5: =IF(AND(N(R5)<>0,AA5=""),1,0)+IF(AND(N(S5)<>0,AB5=""),1,0)+IF(AND(N(L5)<>0,AC5=""),1,0)+IF(AND(N(U5)<>0,AD5=""),1,0)+IF(AND(N(T5)<>0,AE5=""),1,0)
R6: =ROUND(N(H6)*N(J6)-N(K6),2) | S6: =ROUND(R6*IFERROR(VLOOKUP(P6,'Tax Codes'!$A$5:$E$300,5,FALSE),0),2) | T6: =ROUND(R6*IFERROR(VLOOKUP(Q6,'Tax Codes'!$A$5:$E$300,5,FALSE),0),2) | U6: =R6+S6-T6-N(L6) | V6: =IF(C6="",INDEX('Chart of Accounts'!$A$5:$A$3000,MATCH("materials",'Chart of Accounts'!$F$5:$F$3000,0)),C6&"") | W6: =IF(N6="",INDEX('Chart of Accounts'!$A$5:$A$3000,MATCH("bank",'Chart of Accounts'!$F$5:$F$3000,0)),N6&"") | X6: =IF(O6="",INDEX('Chart of Accounts'!$A$5:$A$3000,MATCH("ap",'Chart of Accounts'!$F$5:$F$3000,0)),O6&"") | Y6: =INDEX('Chart of Accounts'!$A$5:$A$3000,MATCH("vat_input",'Chart of Accounts'!$F$5:$F$3000,0)) | Z6: =INDEX('Chart of Accounts'!$A$5:$A$3000,MATCH("wht_payable",'Chart of Accounts'!$F$5:$F$3000,0)) | AA6: =IFERROR(INDEX('Chart of Accounts'!$C$5:$C$3000,MATCH(V6&"",'Chart of Accounts'!$A$5:$A$3000,0))&"|"&INDEX('Chart of Accounts'!$D$5:$D$3000,MATCH(V6&"",'Chart of Accounts'!$A$5:$A$3000,0)),"") | AB6: =IFERROR(INDEX('Chart of Accounts'!$C$5:$C$3000,MATCH(Y6&"",'Chart of Accounts'!$A$5:$A$3000,0))&"|"&INDEX('Chart of Accounts'!$D$5:$D$3000,MATCH(Y6&"",'Chart of Accounts'!$A$5:$A$3000,0)),"") | AC6: =IFERROR(INDEX('Chart of Accounts'!$C$5:$C$3000,MATCH(W6&"",'Chart of Accounts'!$A$5:$A$3000,0))&"|"&INDEX('Chart of Accounts'!$D$5:$D$3000,MATCH(W6&"",'Chart of Accounts'!$A$5:$A$3000,0)),"") | AD6: =IFERROR(INDEX('Chart of Accounts'!$C$5:$C$3000,MATCH(X6&"",'Chart of Accounts'!$A$5:$A$3000,0))&"|"&INDEX('Chart of Accounts'!$D$5:$D$3000,MATCH(X6&"",'Chart of Accounts'!$A$5:$A$3000,0)),"") | AE6: =IFERROR(INDEX('Chart of Accounts'!$C$5:$C$3000,MATCH(Z6&"",'Chart of Accounts'!$A$5:$A$3000,0))&"|"&INDEX('Chart of Accounts'!$D$5:$D$3000,MATCH(Z6&"",'Chart of Accounts'!$A$5:$A$3000,0)),"") | AF6: =IF(LEFT(AA6,8)="Revenue|",-N(R6),0)+IF(LEFT(AB6,8)="Revenue|",-N(S6),0)+IF(LEFT(AC6,8)="Revenue|",N(L6),0)+IF(LEFT(AD6,8)="Revenue|",N(U6),0)+IF(LEFT(AE6,8)="Revenue|",N(T6),0) | AG6: =IF(LEFT(AA6,5)="COGS|",N(R6),0)+IF(LEFT(AB6,5)="COGS|",N(S6),0)+IF(LEFT(AC6,5)="COGS|",-N(L6),0)+IF(LEFT(AD6,5)="COGS|",-N(U6),0)+IF(LEFT(AE6,5)="COGS|",-N(T6),0) | AH6: =IF(LEFT(AA6,8)="Expense|",N(R6),0)+IF(LEFT(AB6,8)="Expense|",N(S6),0)+IF(LEFT(AC6,8)="Expense|",-N(L6),0)+IF(LEFT(AD6,8)="Expense|",-N(U6),0)+IF(LEFT(AE6,8)="Expense|",-N(T6),0) | AI6: =IF(ISNUMBER(MATCH(AA6,{"Expense|employee","Expense|general_admin","Expense|marketing","Expense|utilities","Expense|other_operating"},0)),N(R6),0)+IF(ISNUMBER(MATCH(AB6,{"Expense|employee","Expense|general_admin","Expense|marketing","Expense|utilities","Expense|other_operating"},0)),N(S6),0)+IF(ISNUMBER(MATCH(AC6,{"Expense|employee","Expense|general_admin","Expense|marketing","Expense|utilities","Expense|other_operating"},0)),-N(L6),0)+IF(ISNUMBER(MATCH(AD6,{"Expense|employee","Expense|general_admin","Expense|marketing","Expense|utilities","Expense|other_operating"},0)),-N(U6),0)+IF(ISNUMBER(MATCH(AE6,{"Expense|employee","Expense|general_admin","Expense|marketing","Expense|utilities","Expense|other_operating"},0)),-N(T6),0) | AJ6: =IF(AA6="Liability|payable",-N(R6),0)+IF(AB6="Liability|payable",-N(S6),0)+IF(AC6="Liability|payable",N(L6),0)+IF(AD6="Liability|payable",N(U6),0)+IF(AE6="Liability|payable",N(T6),0) | AK6: =IF(AA6="Liability|accrued",-N(R6),0)+IF(AB6="Liability|accrued",-N(S6),0)+IF(AC6="Liability|accrued",N(L6),0)+IF(AD6="Liability|accrued",N(U6),0)+IF(AE6="Liability|accrued",N(T6),0) | AL6: =IF(AND(N(R6)<>0,AA6=""),1,0)+IF(AND(N(S6)<>0,AB6=""),1,0)+IF(AND(N(L6)<>0,AC6=""),1,0)+IF(AND(N(U6)<>0,AD6=""),1,0)+IF(AND(N(T6)<>0,AE6=""),1,0)
R7: =ROUND(N(H7)*N(J7)-N(K7),2) | S7: =ROUND(R7*IFERROR(VLOOKUP(P7,'Tax Codes'!$A$5:$E$300,5,FALSE),0),2) | T7: =ROUND(R7*IFERROR(VLOOKUP(Q7,'Tax Codes'!$A$5:$E$300,5,FALSE),0),2) | U7: =R7+S7-T7-N(L7) | V7: =IF(C7="",INDEX('Chart of Accounts'!$A$5:$A$3000,MATCH("materials",'Chart of Accounts'!$F$5:$F$3000,0)),C7&"") | W7: =IF(N7="",INDEX('Chart of Accounts'!$A$5:$A$3000,MATCH("bank",'Chart of Accounts'!$F$5:$F$3000,0)),N7&"") | X7: =IF(O7="",INDEX('Chart of Accounts'!$A$5:$A$3000,MATCH("ap",'Chart of Accounts'!$F$5:$F$3000,0)),O7&"") | Y7: =INDEX('Chart of Accounts'!$A$5:$A$3000,MATCH("vat_input",'Chart of Accounts'!$F$5:$F$3000,0)) | Z7: =INDEX('Chart of Accounts'!$A$5:$A$3000,MATCH("wht_payable",'Chart of Accounts'!$F$5:$F$3000,0)) | AA7: =IFERROR(INDEX('Chart of Accounts'!$C$5:$C$3000,MATCH(V7&"",'Chart of Accounts'!$A$5:$A$3000,0))&"|"&INDEX('Chart of Accounts'!$D$5:$D$3000,MATCH(V7&"",'Chart of Accounts'!$A$5:$A$3000,0)),"") | AB7: =IFERROR(INDEX('Chart of Accounts'!$C$5:$C$3000,MATCH(Y7&"",'Chart of Accounts'!$A$5:$A$3000,0))&"|"&INDEX('Chart of Accounts'!$D$5:$D$3000,MATCH(Y7&"",'Chart of Accounts'!$A$5:$A$3000,0)),"") | AC7: =IFERROR(INDEX('Chart of Accounts'!$C$5:$C$3000,MATCH(W7&"",'Chart of Accounts'!$A$5:$A$3000,0))&"|"&INDEX('Chart of Accounts'!$D$5:$D$3000,MATCH(W7&"",'Chart of Accounts'!$A$5:$A$3000,0)),"") | AD7: =IFERROR(INDEX('Chart of Accounts'!$C$5:$C$3000,MATCH(X7&"",'Chart of Accounts'!$A$5:$A$3000,0))&"|"&INDEX('Chart of Accounts'!$D$5:$D$3000,MATCH(X7&"",'Chart of Accounts'!$A$5:$A$3000,0)),"") | AE7: =IFERROR(INDEX('Chart of Accounts'!$C$5:$C$3000,MATCH(Z7&"",'Chart of Accounts'!$A$5:$A$3000,0))&"|"&INDEX('Chart of Accounts'!$D$5:$D$3000,MATCH(Z7&"",'Chart of Accounts'!$A$5:$A$3000,0)),"") | AF7: =IF(LEFT(AA7,8)="Revenue|",-N(R7),0)+IF(LEFT(AB7,8)="Revenue|",-N(S7),0)+IF(LEFT(AC7,8)="Revenue|",N(L7),0)+IF(LEFT(AD7,8)="Revenue|",N(U7),0)+IF(LEFT(AE7,8)="Revenue|",N(T7),0) | AG7: =IF(LEFT(AA7,5)="COGS|",N(R7),0)+IF(LEFT(AB7,5)="COGS|",N(S7),0)+IF(LEFT(AC7,5)="COGS|",-N(L7),0)+IF(LEFT(AD7,5)="COGS|",-N(U7),0)+IF(LEFT(AE7,5)="COGS|",-N(T7),0) | AH7: =IF(LEFT(AA7,8)="Expense|",N(R7),0)+IF(LEFT(AB7,8)="Expense|",N(S7),0)+IF(LEFT(AC7,8)="Expense|",-N(L7),0)+IF(LEFT(AD7,8)="Expense|",-N(U7),0)+IF(LEFT(AE7,8)="Expense|",-N(T7),0) | AI7: =IF(ISNUMBER(MATCH(AA7,{"Expense|employee","Expense|general_admin","Expense|marketing","Expense|utilities","Expense|other_operating"},0)),N(R7),0)+IF(ISNUMBER(MATCH(AB7,{"Expense|employee","Expense|general_admin","Expense|marketing","Expense|utilities","Expense|other_operating"},0)),N(S7),0)+IF(ISNUMBER(MATCH(AC7,{"Expense|employee","Expense|general_admin","Expense|marketing","Expense|utilities","Expense|other_operating"},0)),-N(L7),0)+IF(ISNUMBER(MATCH(AD7,{"Expense|employee","Expense|general_admin","Expense|marketing","Expense|utilities","Expense|other_operating"},0)),-N(U7),0)+IF(ISNUMBER(MATCH(AE7,{"Expense|employee","Expense|general_admin","Expense|marketing","Expense|utilities","Expense|other_operating"},0)),-N(T7),0) | AJ7: =IF(AA7="Liability|payable",-N(R7),0)+IF(AB7="Liability|payable",-N(S7),0)+IF(AC7="Liability|payable",N(L7),0)+IF(AD7="Liability|payable",N(U7),0)+IF(AE7="Liability|payable",N(T7),0) | AK7: =IF(AA7="Liability|accrued",-N(R7),0)+IF(AB7="Liability|accrued",-N(S7),0)+IF(AC7="Liability|accrued",N(L7),0)+IF(AD7="Liability|accrued",N(U7),0)+IF(AE7="Liability|accrued",N(T7),0) | AL7: =IF(AND(N(R7)<>0,AA7=""),1,0)+IF(AND(N(S7)<>0,AB7=""),1,0)+IF(AND(N(L7)<>0,AC7=""),1,0)+IF(AND(N(U7)<>0,AD7=""),1,0)+IF(AND(N(T7)<>0,AE7=""),1,0)
R8: =ROUND(N(H8)*N(J8)-N(K8),2) | S8: =ROUND(R8*IFERROR(VLOOKUP(P8,'Tax Codes'!$A$5:$E$300,5,FALSE),0),2) | T8: =ROUND(R8*IFERROR(VLOOKUP(Q8,'Tax Codes'!$A$5:$E$300,5,FALSE),0),2) | U8: =R8+S8-T8-N(L8) | V8: =IF(C8="",INDEX('Chart of Accounts'!$A$5:$A$3000,MATCH("materials",'Chart of Accounts'!$F$5:$F$3000,0)),C8&"") | W8: =IF(N8="",INDEX('Chart of Accounts'!$A$5:$A$3000,MATCH("bank",'Chart of Accounts'!$F$5:$F$3000,0)),N8&"") | X8: =IF(O8="",INDEX('Chart of Accounts'!$A$5:$A$3000,MATCH("ap",'Chart of Accounts'!$F$5:$F$3000,0)),O8&"") | Y8: =INDEX('Chart of Accounts'!$A$5:$A$3000,MATCH("vat_input",'Chart of Accounts'!$F$5:$F$3000,0)) | Z8: =INDEX('Chart of Accounts'!$A$5:$A$3000,MATCH("wht_payable",'Chart of Accounts'!$F$5:$F$3000,0)) | AA8: =IFERROR(INDEX('Chart of Accounts'!$C$5:$C$3000,MATCH(V8&"",'Chart of Accounts'!$A$5:$A$3000,0))&"|"&INDEX('Chart of Accounts'!$D$5:$D$3000,MATCH(V8&"",'Chart of Accounts'!$A$5:$A$3000,0)),"") | AB8: =IFERROR(INDEX('Chart of Accounts'!$C$5:$C$3000,MATCH(Y8&"",'Chart of Accounts'!$A$5:$A$3000,0))&"|"&INDEX('Chart of Accounts'!$D$5:$D$3000,MATCH(Y8&"",'Chart of Accounts'!$A$5:$A$3000,0)),"") | AC8: =IFERROR(INDEX('Chart of Accounts'!$C$5:$C$3000,MATCH(W8&"",'Chart of Accounts'!$A$5:$A$3000,0))&"|"&INDEX('Chart of Accounts'!$D$5:$D$3000,MATCH(W8&"",'Chart of Accounts'!$A$5:$A$3000,0)),"") | AD8: =IFERROR(INDEX('Chart of Accounts'!$C$5:$C$3000,MATCH(X8&"",'Chart of Accounts'!$A$5:$A$3000,0))&"|"&INDEX('Chart of Accounts'!$D$5:$D$3000,MATCH(X8&"",'Chart of Accounts'!$A$5:$A$3000,0)),"") | AE8: =IFERROR(INDEX('Chart of Accounts'!$C$5:$C$3000,MATCH(Z8&"",'Chart of Accounts'!$A$5:$A$3000,0))&"|"&INDEX('Chart of Accounts'!$D$5:$D$3000,MATCH(Z8&"",'Chart of Accounts'!$A$5:$A$3000,0)),"") | AF8: =IF(LEFT(AA8,8)="Revenue|",-N(R8),0)+IF(LEFT(AB8,8)="Revenue|",-N(S8),0)+IF(LEFT(AC8,8)="Revenue|",N(L8),0)+IF(LEFT(AD8,8)="Revenue|",N(U8),0)+IF(LEFT(AE8,8)="Revenue|",N(T8),0) | AG8: =IF(LEFT(AA8,5)="COGS|",N(R8),0)+IF(LEFT(AB8,5)="COGS|",N(S8),0)+IF(LEFT(AC8,5)="COGS|",-N(L8),0)+IF(LEFT(AD8,5)="COGS|",-N(U8),0)+IF(LEFT(AE8,5)="COGS|",-N(T8),0) | AH8: =IF(LEFT(AA8,8)="Expense|",N(R8),0)+IF(LEFT(AB8,8)="Expense|",N(S8),0)+IF(LEFT(AC8,8)="Expense|",-N(L8),0)+IF(LEFT(AD8,8)="Expense|",-N(U8),0)+IF(LEFT(AE8,8)="Expense|",-N(T8),0) | AI8: =IF(ISNUMBER(MATCH(AA8,{"Expense|employee","Expense|general_admin","Expense|marketing","Expense|utilities","Expense|other_operating"},0)),N(R8),0)+IF(ISNUMBER(MATCH(AB8,{"Expense|employee","Expense|general_admin","Expense|marketing","Expense|utilities","Expense|other_operating"},0)),N(S8),0)+IF(ISNUMBER(MATCH(AC8,{"Expense|employee","Expense|general_admin","Expense|marketing","Expense|utilities","Expense|other_operating"},0)),-N(L8),0)+IF(ISNUMBER(MATCH(AD8,{"Expense|employee","Expense|general_admin","Expense|marketing","Expense|utilities","Expense|other_operating"},0)),-N(U8),0)+IF(ISNUMBER(MATCH(AE8,{"Expense|employee","Expense|general_admin","Expense|marketing","Expense|utilities","Expense|other_operating"},0)),-N(T8),0) | AJ8: =IF(AA8="Liability|payable",-N(R8),0)+IF(AB8="Liability|payable",-N(S8),0)+IF(AC8="Liability|payable",N(L8),0)+IF(AD8="Liability|payable",N(U8),0)+IF(AE8="Liability|payable",N(T8),0) | AK8: =IF(AA8="Liability|accrued",-N(R8),0)+IF(AB8="Liability|accrued",-N(S8),0)+IF(AC8="Liability|accrued",N(L8),0)+IF(AD8="Liability|accrued",N(U8),0)+IF(AE8="Liability|accrued",N(T8),0) | AL8: =IF(AND(N(R8)<>0,AA8=""),1,0)+IF(AND(N(S8)<>0,AB8=""),1,0)+IF(AND(N(L8)<>0,AC8=""),1,0)+IF(AND(N(U8)<>0,AD8=""),1,0)+IF(AND(N(T8)<>0,AE8=""),1,0)
R9: =ROUND(N(H9)*N(J9)-N(K9),2) | S9: =ROUND(R9*IFERROR(VLOOKUP(P9,'Tax Codes'!$A$5:$E$300,5,FALSE),0),2) | T9: =ROUND(R9*IFERROR(VLOOKUP(Q9,'Tax Codes'!$A$5:$E$300,5,FALSE),0),2) | U9: =R9+S9-T9-N(L9) | V9: =IF(C9="",INDEX('Chart of Accounts'!$A$5:$A$3000,MATCH("materials",'Chart of Accounts'!$F$5:$F$3000,0)),C9&"") | W9: =IF(N9="",INDEX('Chart of Accounts'!$A$5:$A$3000,MATCH("bank",'Chart of Accounts'!$F$5:$F$3000,0)),N9&"") | X9: =IF(O9="",INDEX('Chart of Accounts'!$A$5:$A$3000,MATCH("ap",'Chart of Accounts'!$F$5:$F$3000,0)),O9&"") | Y9: =INDEX('Chart of Accounts'!$A$5:$A$3000,MATCH("vat_input",'Chart of Accounts'!$F$5:$F$3000,0)) | Z9: =INDEX('Chart of Accounts'!$A$5:$A$3000,MATCH("wht_payable",'Chart of Accounts'!$F$5:$F$3000,0)) | AA9: =IFERROR(INDEX('Chart of Accounts'!$C$5:$C$3000,MATCH(V9&"",'Chart of Accounts'!$A$5:$A$3000,0))&"|"&INDEX('Chart of Accounts'!$D$5:$D$3000,MATCH(V9&"",'Chart of Accounts'!$A$5:$A$3000,0)),"") | AB9: =IFERROR(INDEX('Chart of Accounts'!$C$5:$C$3000,MATCH(Y9&"",'Chart of Accounts'!$A$5:$A$3000,0))&"|"&INDEX('Chart of Accounts'!$D$5:$D$3000,MATCH(Y9&"",'Chart of Accounts'!$A$5:$A$3000,0)),"") | AC9: =IFERROR(INDEX('Chart of Accounts'!$C$5:$C$3000,MATCH(W9&"",'Chart of Accounts'!$A$5:$A$3000,0))&"|"&INDEX('Chart of Accounts'!$D$5:$D$3000,MATCH(W9&"",'Chart of Accounts'!$A$5:$A$3000,0)),"") | AD9: =IFERROR(INDEX('Chart of Accounts'!$C$5:$C$3000,MATCH(X9&"",'Chart of Accounts'!$A$5:$A$3000,0))&"|"&INDEX('Chart of Accounts'!$D$5:$D$3000,MATCH(X9&"",'Chart of Accounts'!$A$5:$A$3000,0)),"") | AE9: =IFERROR(INDEX('Chart of Accounts'!$C$5:$C$3000,MATCH(Z9&"",'Chart of Accounts'!$A$5:$A$3000,0))&"|"&INDEX('Chart of Accounts'!$D$5:$D$3000,MATCH(Z9&"",'Chart of Accounts'!$A$5:$A$3000,0)),"") | AF9: =IF(LEFT(AA9,8)="Revenue|",-N(R9),0)+IF(LEFT(AB9,8)="Revenue|",-N(S9),0)+IF(LEFT(AC9,8)="Revenue|",N(L9),0)+IF(LEFT(AD9,8)="Revenue|",N(U9),0)+IF(LEFT(AE9,8)="Revenue|",N(T9),0) | AG9: =IF(LEFT(AA9,5)="COGS|",N(R9),0)+IF(LEFT(AB9,5)="COGS|",N(S9),0)+IF(LEFT(AC9,5)="COGS|",-N(L9),0)+IF(LEFT(AD9,5)="COGS|",-N(U9),0)+IF(LEFT(AE9,5)="COGS|",-N(T9),0) | AH9: =IF(LEFT(AA9,8)="Expense|",N(R9),0)+IF(LEFT(AB9,8)="Expense|",N(S9),0)+IF(LEFT(AC9,8)="Expense|",-N(L9),0)+IF(LEFT(AD9,8)="Expense|",-N(U9),0)+IF(LEFT(AE9,8)="Expense|",-N(T9),0) | AI9: =IF(ISNUMBER(MATCH(AA9,{"Expense|employee","Expense|general_admin","Expense|marketing","Expense|utilities","Expense|other_operating"},0)),N(R9),0)+IF(ISNUMBER(MATCH(AB9,{"Expense|employee","Expense|general_admin","Expense|marketing","Expense|utilities","Expense|other_operating"},0)),N(S9),0)+IF(ISNUMBER(MATCH(AC9,{"Expense|employee","Expense|general_admin","Expense|marketing","Expense|utilities","Expense|other_operating"},0)),-N(L9),0)+IF(ISNUMBER(MATCH(AD9,{"Expense|employee","Expense|general_admin","Expense|marketing","Expense|utilities","Expense|other_operating"},0)),-N(U9),0)+IF(ISNUMBER(MATCH(AE9,{"Expense|employee","Expense|general_admin","Expense|marketing","Expense|utilities","Expense|other_operating"},0)),-N(T9),0) | AJ9: =IF(AA9="Liability|payable",-N(R9),0)+IF(AB9="Liability|payable",-N(S9),0)+IF(AC9="Liability|payable",N(L9),0)+IF(AD9="Liability|payable",N(U9),0)+IF(AE9="Liability|payable",N(T9),0) | AK9: =IF(AA9="Liability|accrued",-N(R9),0)+IF(AB9="Liability|accrued",-N(S9),0)+IF(AC9="Liability|accrued",N(L9),0)+IF(AD9="Liability|accrued",N(U9),0)+IF(AE9="Liability|accrued",N(T9),0) | AL9: =IF(AND(N(R9)<>0,AA9=""),1,0)+IF(AND(N(S9)<>0,AB9=""),1,0)+IF(AND(N(L9)<>0,AC9=""),1,0)+IF(AND(N(U9)<>0,AD9=""),1,0)+IF(AND(N(T9)<>0,AE9=""),1,0)
R10: =ROUND(N(H10)*N(J10)-N(K10),2) | S10: =ROUND(R10*IFERROR(VLOOKUP(P10,'Tax Codes'!$A$5:$E$300,5,FALSE),0),2) | T10: =ROUND(R10*IFERROR(VLOOKUP(Q10,'Tax Codes'!$A$5:$E$300,5,FALSE),0),2) | U10: =R10+S10-T10-N(L10) | V10: =IF(C10="",INDEX('Chart of Accounts'!$A$5:$A$3000,MATCH("materials",'Chart of Accounts'!$F$5:$F$3000,0)),C10&"") | W10: =IF(N10="",INDEX('Chart of Accounts'!$A$5:$A$3000,MATCH("bank",'Chart of Accounts'!$F$5:$F$3000,0)),N10&"") | X10: =IF(O10="",INDEX('Chart of Accounts'!$A$5:$A$3000,MATCH("ap",'Chart of Accounts'!$F$5:$F$3000,0)),O10&"") | Y10: =INDEX('Chart of Accounts'!$A$5:$A$3000,MATCH("vat_input",'Chart of Accounts'!$F$5:$F$3000,0)) | Z10: =INDEX('Chart of Accounts'!$A$5:$A$3000,MATCH("wht_payable",'Chart of Accounts'!$F$5:$F$3000,0)) | AA10: =IFERROR(INDEX('Chart of Accounts'!$C$5:$C$3000,MATCH(V10&"",'Chart of Accounts'!$A$5:$A$3000,0))&"|"&INDEX('Chart of Accounts'!$D$5:$D$3000,MATCH(V10&"",'Chart of Accounts'!$A$5:$A$3000,0)),"") | AB10: =IFERROR(INDEX('Chart of Accounts'!$C$5:$C$3000,MATCH(Y10&"",'Chart of Accounts'!$A$5:$A$3000,0))&"|"&INDEX('Chart of Accounts'!$D$5:$D$3000,MATCH(Y10&"",'Chart of Accounts'!$A$5:$A$3000,0)),"") | AC10: =IFERROR(INDEX('Chart of Accounts'!$C$5:$C$3000,MATCH(W10&"",'Chart of Accounts'!$A$5:$A$3000,0))&"|"&INDEX('Chart of Accounts'!$D$5:$D$3000,MATCH(W10&"",'Chart of Accounts'!$A$5:$A$3000,0)),"") | AD10: =IFERROR(INDEX('Chart of Accounts'!$C$5:$C$3000,MATCH(X10&"",'Chart of Accounts'!$A$5:$A$3000,0))&"|"&INDEX('Chart of Accounts'!$D$5:$D$3000,MATCH(X10&"",'Chart of Accounts'!$A$5:$A$3000,0)),"") | AE10: =IFERROR(INDEX('Chart of Accounts'!$C$5:$C$3000,MATCH(Z10&"",'Chart of Accounts'!$A$5:$A$3000,0))&"|"&INDEX('Chart of Accounts'!$D$5:$D$3000,MATCH(Z10&"",'Chart of Accounts'!$A$5:$A$3000,0)),"") | AF10: =IF(LEFT(AA10,8)="Revenue|",-N(R10),0)+IF(LEFT(AB10,8)="Revenue|",-N(S10),0)+IF(LEFT(AC10,8)="Revenue|",N(L10),0)+IF(LEFT(AD10,8)="Revenue|",N(U10),0)+IF(LEFT(AE10,8)="Revenue|",N(T10),0) | AG10: =IF(LEFT(AA10,5)="COGS|",N(R10),0)+IF(LEFT(AB10,5)="COGS|",N(S10),0)+IF(LEFT(AC10,5)="COGS|",-N(L10),0)+IF(LEFT(AD10,5)="COGS|",-N(U10),0)+IF(LEFT(AE10,5)="COGS|",-N(T10),0) | AH10: =IF(LEFT(AA10,8)="Expense|",N(R10),0)+IF(LEFT(AB10,8)="Expense|",N(S10),0)+IF(LEFT(AC10,8)="Expense|",-N(L10),0)+IF(LEFT(AD10,8)="Expense|",-N(U10),0)+IF(LEFT(AE10,8)="Expense|",-N(T10),0) | AI10: =IF(ISNUMBER(MATCH(AA10,{"Expense|employee","Expense|general_admin","Expense|marketing","Expense|utilities","Expense|other_operating"},0)),N(R10),0)+IF(ISNUMBER(MATCH(AB10,{"Expense|employee","Expense|general_admin","Expense|marketing","Expense|utilities","Expense|other_operating"},0)),N(S10),0)+IF(ISNUMBER(MATCH(AC10,{"Expense|employee","Expense|general_admin","Expense|marketing","Expense|utilities","Expense|other_operating"},0)),-N(L10),0)+IF(ISNUMBER(MATCH(AD10,{"Expense|employee","Expense|general_admin","Expense|marketing","Expense|utilities","Expense|other_operating"},0)),-N(U10),0)+IF(ISNUMBER(MATCH(AE10,{"Expense|employee","Expense|general_admin","Expense|marketing","Expense|utilities","Expense|other_operating"},0)),-N(T10),0) | AJ10: =IF(AA10="Liability|payable",-N(R10),0)+IF(AB10="Liability|payable",-N(S10),0)+IF(AC10="Liability|payable",N(L10),0)+IF(AD10="Liability|payable",N(U10),0)+IF(AE10="Liability|payable",N(T10),0) | AK10: =IF(AA10="Liability|accrued",-N(R10),0)+IF(AB10="Liability|accrued",-N(S10),0)+IF(AC10="Liability|accrued",N(L10),0)+IF(AD10="Liability|accrued",N(U10),0)+IF(AE10="Liability|accrued",N(T10),0) | AL10: =IF(AND(N(R10)<>0,AA10=""),1,0)+IF(AND(N(S10)<>0,AB10=""),1,0)+IF(AND(N(L10)<>0,AC10=""),1,0)+IF(AND(N(U10)<>0,AD10=""),1,0)+IF(AND(N(T10)<>0,AE10=""),1,0)
R11: =ROUND(N(H11)*N(J11)-N(K11),2) | S11: =ROUND(R11*IFERROR(VLOOKUP(P11,'Tax Codes'!$A$5:$E$300,5,FALSE),0),2) | T11: =ROUND(R11*IFERROR(VLOOKUP(Q11,'Tax Codes'!$A$5:$E$300,5,FALSE),0),2) | U11: =R11+S11-T11-N(L11) | V11: =IF(C11="",INDEX('Chart of Accounts'!$A$5:$A$3000,MATCH("materials",'Chart of Accounts'!$F$5:$F$3000,0)),C11&"") | W11: =IF(N11="",INDEX('Chart of Accounts'!$A$5:$A$3000,MATCH("bank",'Chart of Accounts'!$F$5:$F$3000,0)),N11&"") | X11: =IF(O11="",INDEX('Chart of Accounts'!$A$5:$A$3000,MATCH("ap",'Chart of Accounts'!$F$5:$F$3000,0)),O11&"") | Y11: =INDEX('Chart of Accounts'!$A$5:$A$3000,MATCH("vat_input",'Chart of Accounts'!$F$5:$F$3000,0)) | Z11: =INDEX('Chart of Accounts'!$A$5:$A$3000,MATCH("wht_payable",'Chart of Accounts'!$F$5:$F$3000,0)) | AA11: =IFERROR(INDEX('Chart of Accounts'!$C$5:$C$3000,MATCH(V11&"",'Chart of Accounts'!$A$5:$A$3000,0))&"|"&INDEX('Chart of Accounts'!$D$5:$D$3000,MATCH(V11&"",'Chart of Accounts'!$A$5:$A$3000,0)),"") | AB11: =IFERROR(INDEX('Chart of Accounts'!$C$5:$C$3000,MATCH(Y11&"",'Chart of Accounts'!$A$5:$A$3000,0))&"|"&INDEX('Chart of Accounts'!$D$5:$D$3000,MATCH(Y11&"",'Chart of Accounts'!$A$5:$A$3000,0)),"") | AC11: =IFERROR(INDEX('Chart of Accounts'!$C$5:$C$3000,MATCH(W11&"",'Chart of Accounts'!$A$5:$A$3000,0))&"|"&INDEX('Chart of Accounts'!$D$5:$D$3000,MATCH(W11&"",'Chart of Accounts'!$A$5:$A$3000,0)),"") | AD11: =IFERROR(INDEX('Chart of Accounts'!$C$5:$C$3000,MATCH(X11&"",'Chart of Accounts'!$A$5:$A$3000,0))&"|"&INDEX('Chart of Accounts'!$D$5:$D$3000,MATCH(X11&"",'Chart of Accounts'!$A$5:$A$3000,0)),"") | AE11: =IFERROR(INDEX('Chart of Accounts'!$C$5:$C$3000,MATCH(Z11&"",'Chart of Accounts'!$A$5:$A$3000,0))&"|"&INDEX('Chart of Accounts'!$D$5:$D$3000,MATCH(Z11&"",'Chart of Accounts'!$A$5:$A$3000,0)),"") | AF11: =IF(LEFT(AA11,8)="Revenue|",-N(R11),0)+IF(LEFT(AB11,8)="Revenue|",-N(S11),0)+IF(LEFT(AC11,8)="Revenue|",N(L11),0)+IF(LEFT(AD11,8)="Revenue|",N(U11),0)+IF(LEFT(AE11,8)="Revenue|",N(T11),0) | AG11: =IF(LEFT(AA11,5)="COGS|",N(R11),0)+IF(LEFT(AB11,5)="COGS|",N(S11),0)+IF(LEFT(AC11,5)="COGS|",-N(L11),0)+IF(LEFT(AD11,5)="COGS|",-N(U11),0)+IF(LEFT(AE11,5)="COGS|",-N(T11),0) | AH11: =IF(LEFT(AA11,8)="Expense|",N(R11),0)+IF(LEFT(AB11,8)="Expense|",N(S11),0)+IF(LEFT(AC11,8)="Expense|",-N(L11),0)+IF(LEFT(AD11,8)="Expense|",-N(U11),0)+IF(LEFT(AE11,8)="Expense|",-N(T11),0) | AI11: =IF(ISNUMBER(MATCH(AA11,{"Expense|employee","Expense|general_admin","Expense|marketing","Expense|utilities","Expense|other_operating"},0)),N(R11),0)+IF(ISNUMBER(MATCH(AB11,{"Expense|employee","Expense|general_admin","Expense|marketing","Expense|utilities","Expense|other_operating"},0)),N(S11),0)+IF(ISNUMBER(MATCH(AC11,{"Expense|employee","Expense|general_admin","Expense|marketing","Expense|utilities","Expense|other_operating"},0)),-N(L11),0)+IF(ISNUMBER(MATCH(AD11,{"Expense|employee","Expense|general_admin","Expense|marketing","Expense|utilities","Expense|other_operating"},0)),-N(U11),0)+IF(ISNUMBER(MATCH(AE11,{"Expense|employee","Expense|general_admin","Expense|marketing","Expense|utilities","Expense|other_operating"},0)),-N(T11),0) | AJ11: =IF(AA11="Liability|payable",-N(R11),0)+IF(AB11="Liability|payable",-N(S11),0)+IF(AC11="Liability|payable",N(L11),0)+IF(AD11="Liability|payable",N(U11),0)+IF(AE11="Liability|payable",N(T11),0) | AK11: =IF(AA11="Liability|accrued",-N(R11),0)+IF(AB11="Liability|accrued",-N(S11),0)+IF(AC11="Liability|accrued",N(L11),0)+IF(AD11="Liability|accrued",N(U11),0)+IF(AE11="Liability|accrued",N(T11),0) | AL11: =IF(AND(N(R11)<>0,AA11=""),1,0)+IF(AND(N(S11)<>0,AB11=""),1,0)+IF(AND(N(L11)<>0,AC11=""),1,0)+IF(AND(N(U11)<>0,AD11=""),1,0)+IF(AND(N(T11)<>0,AE11=""),1,0)
R12: =ROUND(N(H12)*N(J12)-N(K12),2) | S12: =ROUND(R12*IFERROR(VLOOKUP(P12,'Tax Codes'!$A$5:$E$300,5,FALSE),0),2) | T12: =ROUND(R12*IFERROR(VLOOKUP(Q12,'Tax Codes'!$A$5:$E$300,5,FALSE),0),2) | U12: =R12+S12-T12-N(L12) | V12: =IF(C12="",INDEX('Chart of Accounts'!$A$5:$A$3000,MATCH("materials",'Chart of Accounts'!$F$5:$F$3000,0)),C12&"") | W12: =IF(N12="",INDEX('Chart of Accounts'!$A$5:$A$3000,MATCH("bank",'Chart of Accounts'!$F$5:$F$3000,0)),N12&"") | X12: =IF(O12="",INDEX('Chart of Accounts'!$A$5:$A$3000,MATCH("ap",'Chart of Accounts'!$F$5:$F$3000,0)),O12&"") | Y12: =INDEX('Chart of Accounts'!$A$5:$A$3000,MATCH("vat_input",'Chart of Accounts'!$F$5:$F$3000,0)) | Z12: =INDEX('Chart of Accounts'!$A$5:$A$3000,MATCH("wht_payable",'Chart of Accounts'!$F$5:$F$3000,0)) | AA12: =IFERROR(INDEX('Chart of Accounts'!$C$5:$C$3000,MATCH(V12&"",'Chart of Accounts'!$A$5:$A$3000,0))&"|"&INDEX('Chart of Accounts'!$D$5:$D$3000,MATCH(V12&"",'Chart of Accounts'!$A$5:$A$3000,0)),"") | AB12: =IFERROR(INDEX('Chart of Accounts'!$C$5:$C$3000,MATCH(Y12&"",'Chart of Accounts'!$A$5:$A$3000,0))&"|"&INDEX('Chart of Accounts'!$D$5:$D$3000,MATCH(Y12&"",'Chart of Accounts'!$A$5:$A$3000,0)),"") | AC12: =IFERROR(INDEX('Chart of Accounts'!$C$5:$C$3000,MATCH(W12&"",'Chart of Accounts'!$A$5:$A$3000,0))&"|"&INDEX('Chart of Accounts'!$D$5:$D$3000,MATCH(W12&"",'Chart of Accounts'!$A$5:$A$3000,0)),"") | AD12: =IFERROR(INDEX('Chart of Accounts'!$C$5:$C$3000,MATCH(X12&"",'Chart of Accounts'!$A$5:$A$3000,0))&"|"&INDEX('Chart of Accounts'!$D$5:$D$3000,MATCH(X12&"",'Chart of Accounts'!$A$5:$A$3000,0)),"") | AE12: =IFERROR(INDEX('Chart of Accounts'!$C$5:$C$3000,MATCH(Z12&"",'Chart of Accounts'!$A$5:$A$3000,0))&"|"&INDEX('Chart of Accounts'!$D$5:$D$3000,MATCH(Z12&"",'Chart of Accounts'!$A$5:$A$3000,0)),"") | AF12: =IF(LEFT(AA12,8)="Revenue|",-N(R12),0)+IF(LEFT(AB12,8)="Revenue|",-N(S12),0)+IF(LEFT(AC12,8)="Revenue|",N(L12),0)+IF(LEFT(AD12,8)="Revenue|",N(U12),0)+IF(LEFT(AE12,8)="Revenue|",N(T12),0) | AG12: =IF(LEFT(AA12,5)="COGS|",N(R12),0)+IF(LEFT(AB12,5)="COGS|",N(S12),0)+IF(LEFT(AC12,5)="COGS|",-N(L12),0)+IF(LEFT(AD12,5)="COGS|",-N(U12),0)+IF(LEFT(AE12,5)="COGS|",-N(T12),0) | AH12: =IF(LEFT(AA12,8)="Expense|",N(R12),0)+IF(LEFT(AB12,8)="Expense|",N(S12),0)+IF(LEFT(AC12,8)="Expense|",-N(L12),0)+IF(LEFT(AD12,8)="Expense|",-N(U12),0)+IF(LEFT(AE12,8)="Expense|",-N(T12),0) | AI12: =IF(ISNUMBER(MATCH(AA12,{"Expense|employee","Expense|general_admin","Expense|marketing","Expense|utilities","Expense|other_operating"},0)),N(R12),0)+IF(ISNUMBER(MATCH(AB12,{"Expense|employee","Expense|general_admin","Expense|marketing","Expense|utilities","Expense|other_operating"},0)),N(S12),0)+IF(ISNUMBER(MATCH(AC12,{"Expense|employee","Expense|general_admin","Expense|marketing","Expense|utilities","Expense|other_operating"},0)),-N(L12),0)+IF(ISNUMBER(MATCH(AD12,{"Expense|employee","Expense|general_admin","Expense|marketing","Expense|utilities","Expense|other_operating"},0)),-N(U12),0)+IF(ISNUMBER(MATCH(AE12,{"Expense|employee","Expense|general_admin","Expense|marketing","Expense|utilities","Expense|other_operating"},0)),-N(T12),0) | AJ12: =IF(AA12="Liability|payable",-N(R12),0)+IF(AB12="Liability|payable",-N(S12),0)+IF(AC12="Liability|payable",N(L12),0)+IF(AD12="Liability|payable",N(U12),0)+IF(AE12="Liability|payable",N(T12),0) | AK12: =IF(AA12="Liability|accrued",-N(R12),0)+IF(AB12="Liability|accrued",-N(S12),0)+IF(AC12="Liability|accrued",N(L12),0)+IF(AD12="Liability|accrued",N(U12),0)+IF(AE12="Liability|accrued",N(T12),0) | AL12: =IF(AND(N(R12)<>0,AA12=""),1,0)+IF(AND(N(S12)<>0,AB12=""),1,0)+IF(AND(N(L12)<>0,AC12=""),1,0)+IF(AND(N(U12)<>0,AD12=""),1,0)+IF(AND(N(T12)<>0,AE12=""),1,0)
R13: =ROUND(N(H13)*N(J13)-N(K13),2) | S13: =ROUND(R13*IFERROR(VLOOKUP(P13,'Tax Codes'!$A$5:$E$300,5,FALSE),0),2) | T13: =ROUND(R13*IFERROR(VLOOKUP(Q13,'Tax Codes'!$A$5:$E$300,5,FALSE),0),2) | U13: =R13+S13-T13-N(L13) | V13: =IF(C13="",INDEX('Chart of Accounts'!$A$5:$A$3000,MATCH("materials",'Chart of Accounts'!$F$5:$F$3000,0)),C13&"") | W13: =IF(N13="",INDEX('Chart of Accounts'!$A$5:$A$3000,MATCH("bank",'Chart of Accounts'!$F$5:$F$3000,0)),N13&"") | X13: =IF(O13="",INDEX('Chart of Accounts'!$A$5:$A$3000,MATCH("ap",'Chart of Accounts'!$F$5:$F$3000,0)),O13&"") | Y13: =INDEX('Chart of Accounts'!$A$5:$A$3000,MATCH("vat_input",'Chart of Accounts'!$F$5:$F$3000,0)) | Z13: =INDEX('Chart of Accounts'!$A$5:$A$3000,MATCH("wht_payable",'Chart of Accounts'!$F$5:$F$3000,0)) | AA13: =IFERROR(INDEX('Chart of Accounts'!$C$5:$C$3000,MATCH(V13&"",'Chart of Accounts'!$A$5:$A$3000,0))&"|"&INDEX('Chart of Accounts'!$D$5:$D$3000,MATCH(V13&"",'Chart of Accounts'!$A$5:$A$3000,0)),"") | AB13: =IFERROR(INDEX('Chart of Accounts'!$C$5:$C$3000,MATCH(Y13&"",'Chart of Accounts'!$A$5:$A$3000,0))&"|"&INDEX('Chart of Accounts'!$D$5:$D$3000,MATCH(Y13&"",'Chart of Accounts'!$A$5:$A$3000,0)),"") | AC13: =IFERROR(INDEX('Chart of Accounts'!$C$5:$C$3000,MATCH(W13&"",'Chart of Accounts'!$A$5:$A$3000,0))&"|"&INDEX('Chart of Accounts'!$D$5:$D$3000,MATCH(W13&"",'Chart of Accounts'!$A$5:$A$3000,0)),"") | AD13: =IFERROR(INDEX('Chart of Accounts'!$C$5:$C$3000,MATCH(X13&"",'Chart of Accounts'!$A$5:$A$3000,0))&"|"&INDEX('Chart of Accounts'!$D$5:$D$3000,MATCH(X13&"",'Chart of Accounts'!$A$5:$A$3000,0)),"") | AE13: =IFERROR(INDEX('Chart of Accounts'!$C$5:$C$3000,MATCH(Z13&"",'Chart of Accounts'!$A$5:$A$3000,0))&"|"&INDEX('Chart of Accounts'!$D$5:$D$3000,MATCH(Z13&"",'Chart of Accounts'!$A$5:$A$3000,0)),"") | AF13: =IF(LEFT(AA13,8)="Revenue|",-N(R13),0)+IF(LEFT(AB13,8)="Revenue|",-N(S13),0)+IF(LEFT(AC13,8)="Revenue|",N(L13),0)+IF(LEFT(AD13,8)="Revenue|",N(U13),0)+IF(LEFT(AE13,8)="Revenue|",N(T13),0) | AG13: =IF(LEFT(AA13,5)="COGS|",N(R13),0)+IF(LEFT(AB13,5)="COGS|",N(S13),0)+IF(LEFT(AC13,5)="COGS|",-N(L13),0)+IF(LEFT(AD13,5)="COGS|",-N(U13),0)+IF(LEFT(AE13,5)="COGS|",-N(T13),0) | AH13: =IF(LEFT(AA13,8)="Expense|",N(R13),0)+IF(LEFT(AB13,8)="Expense|",N(S13),0)+IF(LEFT(AC13,8)="Expense|",-N(L13),0)+IF(LEFT(AD13,8)="Expense|",-N(U13),0)+IF(LEFT(AE13,8)="Expense|",-N(T13),0) | AI13: =IF(ISNUMBER(MATCH(AA13,{"Expense|employee","Expense|general_admin","Expense|marketing","Expense|utilities","Expense|other_operating"},0)),N(R13),0)+IF(ISNUMBER(MATCH(AB13,{"Expense|employee","Expense|general_admin","Expense|marketing","Expense|utilities","Expense|other_operating"},0)),N(S13),0)+IF(ISNUMBER(MATCH(AC13,{"Expense|employee","Expense|general_admin","Expense|marketing","Expense|utilities","Expense|other_operating"},0)),-N(L13),0)+IF(ISNUMBER(MATCH(AD13,{"Expense|employee","Expense|general_admin","Expense|marketing","Expense|utilities","Expense|other_operating"},0)),-N(U13),0)+IF(ISNUMBER(MATCH(AE13,{"Expense|employee","Expense|general_admin","Expense|marketing","Expense|utilities","Expense|other_operating"},0)),-N(T13),0) | AJ13: =IF(AA13="Liability|payable",-N(R13),0)+IF(AB13="Liability|payable",-N(S13),0)+IF(AC13="Liability|payable",N(L13),0)+IF(AD13="Liability|payable",N(U13),0)+IF(AE13="Liability|payable",N(T13),0) | AK13: =IF(AA13="Liability|accrued",-N(R13),0)+IF(AB13="Liability|accrued",-N(S13),0)+IF(AC13="Liability|accrued",N(L13),0)+IF(AD13="Liability|accrued",N(U13),0)+IF(AE13="Liability|accrued",N(T13),0) | AL13: =IF(AND(N(R13)<>0,AA13=""),1,0)+IF(AND(N(S13)<>0,AB13=""),1,0)+IF(AND(N(L13)<>0,AC13=""),1,0)+IF(AND(N(U13)<>0,AD13=""),1,0)+IF(AND(N(T13)<>0,AE13=""),1,0)
